[2024-08-23T09:37:01.506+0000] {taskinstance.py:1979} INFO - Dependencies all met for dep_context=non-requeueable deps ti=<TaskInstance: Credit_score_pipeline_v03.extract_data scheduled__2024-08-22T00:00:00+00:00 [queued]>
[2024-08-23T09:37:01.515+0000] {taskinstance.py:1979} INFO - Dependencies all met for dep_context=requeueable deps ti=<TaskInstance: Credit_score_pipeline_v03.extract_data scheduled__2024-08-22T00:00:00+00:00 [queued]>
[2024-08-23T09:37:01.516+0000] {taskinstance.py:2193} INFO - Starting attempt 1 of 6
[2024-08-23T09:37:01.535+0000] {taskinstance.py:2214} INFO - Executing <Task(PythonOperator): extract_data> on 2024-08-22 00:00:00+00:00
[2024-08-23T09:37:01.611+0000] {standard_task_runner.py:60} INFO - Started process 113 to run task
[2024-08-23T09:37:01.704+0000] {standard_task_runner.py:87} INFO - Running: ['***', 'tasks', 'run', 'Credit_score_pipeline_v03', 'extract_data', 'scheduled__2024-08-22T00:00:00+00:00', '--job-id', '287', '--raw', '--subdir', 'DAGS_FOLDER/credit_score.py', '--cfg-path', '/tmp/tmpdd1r7nae']
[2024-08-23T09:37:01.708+0000] {standard_task_runner.py:88} INFO - Job 287: Subtask extract_data
[2024-08-23T09:37:02.294+0000] {task_command.py:423} INFO - Running <TaskInstance: Credit_score_pipeline_v03.extract_data scheduled__2024-08-22T00:00:00+00:00 [running]> on host f022a2ec5bf1
[2024-08-23T09:37:02.901+0000] {taskinstance.py:2510} INFO - Exporting env vars: AIRFLOW_CTX_DAG_OWNER='***' AIRFLOW_CTX_DAG_ID='Credit_score_pipeline_v03' AIRFLOW_CTX_TASK_ID='extract_data' AIRFLOW_CTX_EXECUTION_DATE='2024-08-22T00:00:00+00:00' AIRFLOW_CTX_TRY_NUMBER='1' AIRFLOW_CTX_DAG_RUN_ID='scheduled__2024-08-22T00:00:00+00:00'
[2024-08-23T09:37:02.905+0000] {taskinstance.py:2728} ERROR - Task failed with exception
Traceback (most recent call last):
  File "/home/airflow/.local/lib/python3.8/site-packages/airflow/models/taskinstance.py", line 444, in _execute_task
    result = _execute_callable(context=context, **execute_callable_kwargs)
  File "/home/airflow/.local/lib/python3.8/site-packages/airflow/models/taskinstance.py", line 414, in _execute_callable
    return execute_callable(context=context, **execute_callable_kwargs)
  File "/home/airflow/.local/lib/python3.8/site-packages/airflow/operators/python.py", line 200, in execute
    return_value = self.execute_callable()
  File "/home/airflow/.local/lib/python3.8/site-packages/airflow/operators/python.py", line 217, in execute_callable
    return self.python_callable(*self.op_args, **self.op_kwargs)
  File "/opt/airflow/dags/credit_score.py", line 29, in extract_csv_data
    raise FileNotFoundError(f"The file {file_csv} does not exist")
FileNotFoundError: The file /opt/***/dags/hmeq.csv does not exist
[2024-08-23T09:37:02.929+0000] {taskinstance.py:1149} INFO - Marking task as UP_FOR_RETRY. dag_id=Credit_score_pipeline_v03, task_id=extract_data, execution_date=20240822T000000, start_date=20240823T093701, end_date=20240823T093702
[2024-08-23T09:37:02.981+0000] {standard_task_runner.py:107} ERROR - Failed to execute job 287 for task extract_data (The file /opt/***/dags/hmeq.csv does not exist; 113)
[2024-08-23T09:37:03.012+0000] {local_task_job_runner.py:234} INFO - Task exited with return code 1
[2024-08-23T09:37:03.062+0000] {taskinstance.py:3309} INFO - 0 downstream tasks scheduled from follow-on schedule check
