[2024-08-02T11:34:42.611+0000] {taskinstance.py:1979} INFO - Dependencies all met for dep_context=non-requeueable deps ti=<TaskInstance: finetune_gpt_v1.finetuning_by_GPT manual__2024-08-02T11:34:40.824945+00:00 [queued]>
[2024-08-02T11:34:42.623+0000] {taskinstance.py:1979} INFO - Dependencies all met for dep_context=requeueable deps ti=<TaskInstance: finetune_gpt_v1.finetuning_by_GPT manual__2024-08-02T11:34:40.824945+00:00 [queued]>
[2024-08-02T11:34:42.624+0000] {taskinstance.py:2193} INFO - Starting attempt 1 of 6
[2024-08-02T11:34:42.643+0000] {taskinstance.py:2214} INFO - Executing <Task(PythonOperator): finetuning_by_GPT> on 2024-08-02 11:34:40.824945+00:00
[2024-08-02T11:34:42.651+0000] {standard_task_runner.py:60} INFO - Started process 127 to run task
[2024-08-02T11:34:42.655+0000] {standard_task_runner.py:87} INFO - Running: ['***', 'tasks', 'run', 'finetune_gpt_v1', 'finetuning_by_GPT', 'manual__2024-08-02T11:34:40.824945+00:00', '--job-id', '59', '--raw', '--subdir', 'DAGS_FOLDER/finetune_gpt.py', '--cfg-path', '/tmp/tmp0tj96_qz']
[2024-08-02T11:34:42.658+0000] {standard_task_runner.py:88} INFO - Job 59: Subtask finetuning_by_GPT
[2024-08-02T11:34:42.728+0000] {task_command.py:423} INFO - Running <TaskInstance: finetune_gpt_v1.finetuning_by_GPT manual__2024-08-02T11:34:40.824945+00:00 [running]> on host 763b10b8ea7f
[2024-08-02T11:34:43.079+0000] {taskinstance.py:2510} INFO - Exporting env vars: AIRFLOW_CTX_DAG_OWNER='admin' AIRFLOW_CTX_DAG_ID='finetune_gpt_v1' AIRFLOW_CTX_TASK_ID='finetuning_by_GPT' AIRFLOW_CTX_EXECUTION_DATE='2024-08-02T11:34:40.824945+00:00' AIRFLOW_CTX_TRY_NUMBER='1' AIRFLOW_CTX_DAG_RUN_ID='manual__2024-08-02T11:34:40.824945+00:00'
[2024-08-02T11:34:43.082+0000] {taskinstance.py:2728} ERROR - Task failed with exception
Traceback (most recent call last):
  File "/home/airflow/.local/lib/python3.8/site-packages/airflow/models/taskinstance.py", line 444, in _execute_task
    result = _execute_callable(context=context, **execute_callable_kwargs)
  File "/home/airflow/.local/lib/python3.8/site-packages/airflow/models/taskinstance.py", line 414, in _execute_callable
    return execute_callable(context=context, **execute_callable_kwargs)
  File "/home/airflow/.local/lib/python3.8/site-packages/airflow/operators/python.py", line 200, in execute
    return_value = self.execute_callable()
  File "/home/airflow/.local/lib/python3.8/site-packages/airflow/operators/python.py", line 217, in execute_callable
    return self.python_callable(*self.op_args, **self.op_kwargs)
  File "/opt/airflow/dags/finetune_gpt.py", line 47, in finetuning
    client = openai.OpenAI(api_key='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')
NameError: name 'openai' is not defined
[2024-08-02T11:34:43.102+0000] {taskinstance.py:1149} INFO - Marking task as UP_FOR_RETRY. dag_id=finetune_gpt_v1, task_id=finetuning_by_GPT, execution_date=20240802T113440, start_date=20240802T113442, end_date=20240802T113443
[2024-08-02T11:34:43.123+0000] {standard_task_runner.py:107} ERROR - Failed to execute job 59 for task finetuning_by_GPT (name 'openai' is not defined; 127)
[2024-08-02T11:34:43.149+0000] {local_task_job_runner.py:234} INFO - Task exited with return code 1
[2024-08-02T11:34:43.168+0000] {taskinstance.py:3309} INFO - 0 downstream tasks scheduled from follow-on schedule check
