[2024-08-02T11:40:52.004+0000] {taskinstance.py:1979} INFO - Dependencies all met for dep_context=non-requeueable deps ti=<TaskInstance: finetune_gpt_v1.finetuning_by_GPT manual__2024-08-02T11:34:40.824945+00:00 [queued]>
[2024-08-02T11:40:52.038+0000] {taskinstance.py:1979} INFO - Dependencies all met for dep_context=requeueable deps ti=<TaskInstance: finetune_gpt_v1.finetuning_by_GPT manual__2024-08-02T11:34:40.824945+00:00 [queued]>
[2024-08-02T11:40:52.052+0000] {taskinstance.py:2193} INFO - Starting attempt 3 of 7
[2024-08-02T11:40:52.494+0000] {taskinstance.py:2214} INFO - Executing <Task(PythonOperator): finetuning_by_GPT> on 2024-08-02 11:34:40.824945+00:00
[2024-08-02T11:40:52.504+0000] {standard_task_runner.py:60} INFO - Started process 221 to run task
[2024-08-02T11:40:53.081+0000] {standard_task_runner.py:87} INFO - Running: ['***', 'tasks', 'run', 'finetune_gpt_v1', 'finetuning_by_GPT', 'manual__2024-08-02T11:34:40.824945+00:00', '--job-id', '61', '--raw', '--subdir', 'DAGS_FOLDER/finetune_gpt.py', '--cfg-path', '/tmp/tmpvo265pcv']
[2024-08-02T11:40:53.508+0000] {standard_task_runner.py:88} INFO - Job 61: Subtask finetuning_by_GPT
[2024-08-02T11:41:00.948+0000] {task_command.py:423} INFO - Running <TaskInstance: finetune_gpt_v1.finetuning_by_GPT manual__2024-08-02T11:34:40.824945+00:00 [running]> on host 763b10b8ea7f
[2024-08-02T11:41:04.376+0000] {taskinstance.py:2510} INFO - Exporting env vars: AIRFLOW_CTX_DAG_OWNER='admin' AIRFLOW_CTX_DAG_ID='finetune_gpt_v1' AIRFLOW_CTX_TASK_ID='finetuning_by_GPT' AIRFLOW_CTX_EXECUTION_DATE='2024-08-02T11:34:40.824945+00:00' AIRFLOW_CTX_TRY_NUMBER='3' AIRFLOW_CTX_DAG_RUN_ID='manual__2024-08-02T11:34:40.824945+00:00'
[2024-08-02T11:41:17.353+0000] {taskinstance.py:2728} ERROR - Task failed with exception
Traceback (most recent call last):
  File "/home/airflow/.local/lib/python3.8/site-packages/airflow/models/taskinstance.py", line 444, in _execute_task
    result = _execute_callable(context=context, **execute_callable_kwargs)
  File "/home/airflow/.local/lib/python3.8/site-packages/airflow/models/taskinstance.py", line 414, in _execute_callable
    return execute_callable(context=context, **execute_callable_kwargs)
  File "/home/airflow/.local/lib/python3.8/site-packages/airflow/operators/python.py", line 200, in execute
    return_value = self.execute_callable()
  File "/home/airflow/.local/lib/python3.8/site-packages/airflow/operators/python.py", line 217, in execute_callable
    return self.python_callable(*self.op_args, **self.op_kwargs)
  File "/opt/airflow/dags/finetune_gpt.py", line 52, in finetuning
    response = client.fine_tuning.jobs.create(
  File "/home/airflow/.local/lib/python3.8/site-packages/openai/resources/fine_tuning/jobs/jobs.py", line 133, in create
    return self._post(
  File "/home/airflow/.local/lib/python3.8/site-packages/openai/_base_client.py", line 1266, in post
    return cast(ResponseT, self.request(cast_to, opts, stream=stream, stream_cls=stream_cls))
  File "/home/airflow/.local/lib/python3.8/site-packages/openai/_base_client.py", line 942, in request
    return self._request(
  File "/home/airflow/.local/lib/python3.8/site-packages/openai/_base_client.py", line 1046, in _request
    raise self._make_status_error_from_response(err.response) from None
openai.BadRequestError: Error code: 400 - {'error': {'message': 'Model gpt-4o-mini is not available for fine-tuning or does not exist.', 'type': 'invalid_request_error', 'param': None, 'code': 'model_not_available'}}
[2024-08-02T11:41:18.188+0000] {taskinstance.py:1149} INFO - Marking task as UP_FOR_RETRY. dag_id=finetune_gpt_v1, task_id=finetuning_by_GPT, execution_date=20240802T113440, start_date=20240802T114052, end_date=20240802T114118
[2024-08-02T11:41:18.803+0000] {standard_task_runner.py:107} ERROR - Failed to execute job 61 for task finetuning_by_GPT (Error code: 400 - {'error': {'message': 'Model gpt-4o-mini is not available for fine-tuning or does not exist.', 'type': 'invalid_request_error', 'param': None, 'code': 'model_not_available'}}; 221)
[2024-08-02T11:41:19.150+0000] {local_task_job_runner.py:234} INFO - Task exited with return code 1
[2024-08-02T11:41:19.278+0000] {taskinstance.py:3309} INFO - 0 downstream tasks scheduled from follow-on schedule check
