[2024-08-05T17:07:00.741+0000] {taskinstance.py:1979} INFO - Dependencies all met for dep_context=non-requeueable deps ti=<TaskInstance: Credit_score_pipeline_v04.extract_data scheduled__2024-08-04T00:00:00+00:00 [queued]>
[2024-08-05T17:07:00.749+0000] {taskinstance.py:1979} INFO - Dependencies all met for dep_context=requeueable deps ti=<TaskInstance: Credit_score_pipeline_v04.extract_data scheduled__2024-08-04T00:00:00+00:00 [queued]>
[2024-08-05T17:07:00.750+0000] {taskinstance.py:2193} INFO - Starting attempt 1 of 6
[2024-08-05T17:07:00.767+0000] {taskinstance.py:2214} INFO - Executing <Task(PythonOperator): extract_data> on 2024-08-04 00:00:00+00:00
[2024-08-05T17:07:00.775+0000] {standard_task_runner.py:60} INFO - Started process 1422 to run task
[2024-08-05T17:07:00.778+0000] {standard_task_runner.py:87} INFO - Running: ['***', 'tasks', 'run', 'Credit_score_pipeline_v04', 'extract_data', 'scheduled__2024-08-04T00:00:00+00:00', '--job-id', '163', '--raw', '--subdir', 'DAGS_FOLDER/credit_score.py', '--cfg-path', '/tmp/tmpvf7ief3g']
[2024-08-05T17:07:00.781+0000] {standard_task_runner.py:88} INFO - Job 163: Subtask extract_data
[2024-08-05T17:07:00.835+0000] {task_command.py:423} INFO - Running <TaskInstance: Credit_score_pipeline_v04.extract_data scheduled__2024-08-04T00:00:00+00:00 [running]> on host dd9539b5cbac
[2024-08-05T17:07:00.922+0000] {taskinstance.py:2510} INFO - Exporting env vars: AIRFLOW_CTX_DAG_OWNER='***' AIRFLOW_CTX_DAG_ID='Credit_score_pipeline_v04' AIRFLOW_CTX_TASK_ID='extract_data' AIRFLOW_CTX_EXECUTION_DATE='2024-08-04T00:00:00+00:00' AIRFLOW_CTX_TRY_NUMBER='1' AIRFLOW_CTX_DAG_RUN_ID='scheduled__2024-08-04T00:00:00+00:00'
[2024-08-05T17:07:00.924+0000] {taskinstance.py:2728} ERROR - Task failed with exception
Traceback (most recent call last):
  File "/home/airflow/.local/lib/python3.8/site-packages/airflow/models/taskinstance.py", line 444, in _execute_task
    result = _execute_callable(context=context, **execute_callable_kwargs)
  File "/home/airflow/.local/lib/python3.8/site-packages/airflow/models/taskinstance.py", line 414, in _execute_callable
    return execute_callable(context=context, **execute_callable_kwargs)
  File "/home/airflow/.local/lib/python3.8/site-packages/airflow/operators/python.py", line 200, in execute
    return_value = self.execute_callable()
  File "/home/airflow/.local/lib/python3.8/site-packages/airflow/operators/python.py", line 217, in execute_callable
    return self.python_callable(*self.op_args, **self.op_kwargs)
  File "/opt/airflow/dags/credit_score.py", line 20, in extract_csv_data
    file = pd.read_csv(file_csv)
NameError: name 'pd' is not defined
[2024-08-05T17:07:01.024+0000] {taskinstance.py:1149} INFO - Marking task as UP_FOR_RETRY. dag_id=Credit_score_pipeline_v04, task_id=extract_data, execution_date=20240804T000000, start_date=20240805T170700, end_date=20240805T170701
[2024-08-05T17:07:01.050+0000] {standard_task_runner.py:107} ERROR - Failed to execute job 163 for task extract_data (name 'pd' is not defined; 1422)
[2024-08-05T17:07:01.073+0000] {local_task_job_runner.py:234} INFO - Task exited with return code 1
[2024-08-05T17:07:01.095+0000] {taskinstance.py:3309} INFO - 0 downstream tasks scheduled from follow-on schedule check
