[2024-08-23T09:52:13.495+0000] {taskinstance.py:1979} INFO - Dependencies all met for dep_context=non-requeueable deps ti=<TaskInstance: Credit_score_pipeline_v03.train_test_split scheduled__2024-08-22T00:00:00+00:00 [queued]>
[2024-08-23T09:52:13.522+0000] {taskinstance.py:1979} INFO - Dependencies all met for dep_context=requeueable deps ti=<TaskInstance: Credit_score_pipeline_v03.train_test_split scheduled__2024-08-22T00:00:00+00:00 [queued]>
[2024-08-23T09:52:13.523+0000] {taskinstance.py:2193} INFO - Starting attempt 5 of 10
[2024-08-23T09:52:13.562+0000] {taskinstance.py:2214} INFO - Executing <Task(PythonOperator): train_test_split> on 2024-08-22 00:00:00+00:00
[2024-08-23T09:52:13.587+0000] {standard_task_runner.py:60} INFO - Started process 759 to run task
[2024-08-23T09:52:13.594+0000] {standard_task_runner.py:87} INFO - Running: ['***', 'tasks', 'run', 'Credit_score_pipeline_v03', 'train_test_split', 'scheduled__2024-08-22T00:00:00+00:00', '--job-id', '316', '--raw', '--subdir', 'DAGS_FOLDER/credit_score.py', '--cfg-path', '/tmp/tmph8h00ygs']
[2024-08-23T09:52:13.602+0000] {standard_task_runner.py:88} INFO - Job 316: Subtask train_test_split
[2024-08-23T09:52:13.686+0000] {task_command.py:423} INFO - Running <TaskInstance: Credit_score_pipeline_v03.train_test_split scheduled__2024-08-22T00:00:00+00:00 [running]> on host f022a2ec5bf1
[2024-08-23T09:52:13.802+0000] {taskinstance.py:2510} INFO - Exporting env vars: AIRFLOW_CTX_DAG_OWNER='***' AIRFLOW_CTX_DAG_ID='Credit_score_pipeline_v03' AIRFLOW_CTX_TASK_ID='train_test_split' AIRFLOW_CTX_EXECUTION_DATE='2024-08-22T00:00:00+00:00' AIRFLOW_CTX_TRY_NUMBER='5' AIRFLOW_CTX_DAG_RUN_ID='scheduled__2024-08-22T00:00:00+00:00'
[2024-08-23T09:52:14.032+0000] {taskinstance.py:2728} ERROR - Task failed with exception
Traceback (most recent call last):
  File "/home/airflow/.local/lib/python3.8/site-packages/airflow/models/taskinstance.py", line 444, in _execute_task
    result = _execute_callable(context=context, **execute_callable_kwargs)
  File "/home/airflow/.local/lib/python3.8/site-packages/airflow/models/taskinstance.py", line 414, in _execute_callable
    return execute_callable(context=context, **execute_callable_kwargs)
  File "/home/airflow/.local/lib/python3.8/site-packages/airflow/operators/python.py", line 200, in execute
    return_value = self.execute_callable()
  File "/home/airflow/.local/lib/python3.8/site-packages/airflow/operators/python.py", line 217, in execute_callable
    return self.python_callable(*self.op_args, **self.op_kwargs)
  File "/opt/airflow/dags/credit_score.py", line 123, in split_train_test
    test_data.to_csv('/opt/airflow/dags/test_data.csv',index = False)
  File "/home/airflow/.local/lib/python3.8/site-packages/pandas/core/generic.py", line 3772, in to_csv
    return DataFrameRenderer(formatter).to_csv(
  File "/home/airflow/.local/lib/python3.8/site-packages/pandas/io/formats/format.py", line 1186, in to_csv
    csv_formatter.save()
  File "/home/airflow/.local/lib/python3.8/site-packages/pandas/io/formats/csvs.py", line 240, in save
    with get_handle(
  File "/home/airflow/.local/lib/python3.8/site-packages/pandas/io/common.py", line 859, in get_handle
    handle = open(
PermissionError: [Errno 13] Permission denied: '/opt/airflow/dags/test_data.csv'
[2024-08-23T09:52:14.048+0000] {taskinstance.py:1149} INFO - Marking task as UP_FOR_RETRY. dag_id=Credit_score_pipeline_v03, task_id=train_test_split, execution_date=20240822T000000, start_date=20240823T095213, end_date=20240823T095214
[2024-08-23T09:52:14.066+0000] {standard_task_runner.py:107} ERROR - Failed to execute job 316 for task train_test_split ([Errno 13] Permission denied: '/opt/airflow/dags/test_data.csv'; 759)
[2024-08-23T09:52:14.091+0000] {local_task_job_runner.py:234} INFO - Task exited with return code 1
[2024-08-23T09:52:14.121+0000] {taskinstance.py:3309} INFO - 0 downstream tasks scheduled from follow-on schedule check
