[2024-08-02T08:43:29.120+0000] {taskinstance.py:1979} INFO - Dependencies all met for dep_context=non-requeueable deps ti=<TaskInstance: dag_with_python_dependencies_v01.get_sklearn manual__2024-08-02T08:18:29.058946+00:00 [queued]>
[2024-08-02T08:43:29.138+0000] {taskinstance.py:1979} INFO - Dependencies all met for dep_context=requeueable deps ti=<TaskInstance: dag_with_python_dependencies_v01.get_sklearn manual__2024-08-02T08:18:29.058946+00:00 [queued]>
[2024-08-02T08:43:29.139+0000] {taskinstance.py:2193} INFO - Starting attempt 4 of 4
[2024-08-02T08:43:29.168+0000] {taskinstance.py:2214} INFO - Executing <Task(PythonOperator): get_sklearn> on 2024-08-02 08:18:29.058946+00:00
[2024-08-02T08:43:29.177+0000] {standard_task_runner.py:60} INFO - Started process 283 to run task
[2024-08-02T08:43:29.183+0000] {standard_task_runner.py:87} INFO - Running: ['***', 'tasks', 'run', 'dag_with_python_dependencies_v01', 'get_sklearn', 'manual__2024-08-02T08:18:29.058946+00:00', '--job-id', '12', '--raw', '--subdir', 'DAGS_FOLDER/dag_with_python_dependencies.py', '--cfg-path', '/tmp/tmp3ea79ppa']
[2024-08-02T08:43:29.187+0000] {standard_task_runner.py:88} INFO - Job 12: Subtask get_sklearn
[2024-08-02T08:43:29.283+0000] {task_command.py:423} INFO - Running <TaskInstance: dag_with_python_dependencies_v01.get_sklearn manual__2024-08-02T08:18:29.058946+00:00 [running]> on host a2959b7f6606
[2024-08-02T08:43:29.416+0000] {taskinstance.py:2510} INFO - Exporting env vars: AIRFLOW_CTX_DAG_OWNER='***' AIRFLOW_CTX_DAG_ID='dag_with_python_dependencies_v01' AIRFLOW_CTX_TASK_ID='get_sklearn' AIRFLOW_CTX_EXECUTION_DATE='2024-08-02T08:18:29.058946+00:00' AIRFLOW_CTX_TRY_NUMBER='4' AIRFLOW_CTX_DAG_RUN_ID='manual__2024-08-02T08:18:29.058946+00:00'
[2024-08-02T08:43:29.419+0000] {taskinstance.py:2728} ERROR - Task failed with exception
Traceback (most recent call last):
  File "/home/airflow/.local/lib/python3.8/site-packages/airflow/models/taskinstance.py", line 444, in _execute_task
    result = _execute_callable(context=context, **execute_callable_kwargs)
  File "/home/airflow/.local/lib/python3.8/site-packages/airflow/models/taskinstance.py", line 414, in _execute_callable
    return execute_callable(context=context, **execute_callable_kwargs)
  File "/home/airflow/.local/lib/python3.8/site-packages/airflow/operators/python.py", line 200, in execute
    return_value = self.execute_callable()
  File "/home/airflow/.local/lib/python3.8/site-packages/airflow/operators/python.py", line 217, in execute_callable
    return self.python_callable(*self.op_args, **self.op_kwargs)
  File "/opt/airflow/dags/dag_with_python_dependencies.py", line 12, in get_sklearn
    import sklearn
ModuleNotFoundError: No module named 'sklearn'
[2024-08-02T08:43:29.435+0000] {taskinstance.py:1149} INFO - Marking task as FAILED. dag_id=dag_with_python_dependencies_v01, task_id=get_sklearn, execution_date=20240802T081829, start_date=20240802T084329, end_date=20240802T084329
[2024-08-02T08:43:29.453+0000] {standard_task_runner.py:107} ERROR - Failed to execute job 12 for task get_sklearn (No module named 'sklearn'; 283)
[2024-08-02T08:43:29.476+0000] {local_task_job_runner.py:234} INFO - Task exited with return code 1
[2024-08-02T08:43:29.504+0000] {taskinstance.py:3309} INFO - 0 downstream tasks scheduled from follow-on schedule check
