[2024-08-02T08:43:13.268+0000] {taskinstance.py:1979} INFO - Dependencies all met for dep_context=non-requeueable deps ti=<TaskInstance: dag_with_python_dependencies_v01.get_sklearn manual__2024-08-02T08:18:29.058946+00:00 [queued]>
[2024-08-02T08:43:13.290+0000] {taskinstance.py:1979} INFO - Dependencies all met for dep_context=requeueable deps ti=<TaskInstance: dag_with_python_dependencies_v01.get_sklearn manual__2024-08-02T08:18:29.058946+00:00 [queued]>
[2024-08-02T08:43:13.292+0000] {taskinstance.py:2193} INFO - Starting attempt 3 of 3
[2024-08-02T08:43:13.324+0000] {taskinstance.py:2214} INFO - Executing <Task(PythonOperator): get_sklearn> on 2024-08-02 08:18:29.058946+00:00
[2024-08-02T08:43:13.333+0000] {standard_task_runner.py:60} INFO - Started process 281 to run task
[2024-08-02T08:43:13.339+0000] {standard_task_runner.py:87} INFO - Running: ['***', 'tasks', 'run', 'dag_with_python_dependencies_v01', 'get_sklearn', 'manual__2024-08-02T08:18:29.058946+00:00', '--job-id', '11', '--raw', '--subdir', 'DAGS_FOLDER/dag_with_python_dependencies.py', '--cfg-path', '/tmp/tmps_2rtn9u']
[2024-08-02T08:43:13.342+0000] {standard_task_runner.py:88} INFO - Job 11: Subtask get_sklearn
[2024-08-02T08:43:13.460+0000] {task_command.py:423} INFO - Running <TaskInstance: dag_with_python_dependencies_v01.get_sklearn manual__2024-08-02T08:18:29.058946+00:00 [running]> on host a2959b7f6606
[2024-08-02T08:43:13.559+0000] {taskinstance.py:2510} INFO - Exporting env vars: AIRFLOW_CTX_DAG_OWNER='***' AIRFLOW_CTX_DAG_ID='dag_with_python_dependencies_v01' AIRFLOW_CTX_TASK_ID='get_sklearn' AIRFLOW_CTX_EXECUTION_DATE='2024-08-02T08:18:29.058946+00:00' AIRFLOW_CTX_TRY_NUMBER='3' AIRFLOW_CTX_DAG_RUN_ID='manual__2024-08-02T08:18:29.058946+00:00'
[2024-08-02T08:43:13.564+0000] {taskinstance.py:2728} ERROR - Task failed with exception
Traceback (most recent call last):
  File "/home/airflow/.local/lib/python3.8/site-packages/airflow/models/taskinstance.py", line 444, in _execute_task
    result = _execute_callable(context=context, **execute_callable_kwargs)
  File "/home/airflow/.local/lib/python3.8/site-packages/airflow/models/taskinstance.py", line 414, in _execute_callable
    return execute_callable(context=context, **execute_callable_kwargs)
  File "/home/airflow/.local/lib/python3.8/site-packages/airflow/operators/python.py", line 200, in execute
    return_value = self.execute_callable()
  File "/home/airflow/.local/lib/python3.8/site-packages/airflow/operators/python.py", line 217, in execute_callable
    return self.python_callable(*self.op_args, **self.op_kwargs)
  File "/opt/airflow/dags/dag_with_python_dependencies.py", line 12, in get_sklearn
    import sklearn
ModuleNotFoundError: No module named 'sklearn'
[2024-08-02T08:43:13.578+0000] {taskinstance.py:1149} INFO - Marking task as FAILED. dag_id=dag_with_python_dependencies_v01, task_id=get_sklearn, execution_date=20240802T081829, start_date=20240802T084313, end_date=20240802T084313
[2024-08-02T08:43:13.595+0000] {standard_task_runner.py:107} ERROR - Failed to execute job 11 for task get_sklearn (No module named 'sklearn'; 281)
[2024-08-02T08:43:13.638+0000] {local_task_job_runner.py:234} INFO - Task exited with return code 1
[2024-08-02T08:43:13.669+0000] {taskinstance.py:3309} INFO - 0 downstream tasks scheduled from follow-on schedule check
